Workbook

Sheet Read Me
A1: Denver Metro Healthcare Market — Account Universe
A2: Prepared for Kristin Boothart | Hillyard, Inc. — District Sales Manager, Denver | Compiled August 14, 2026
A5: WHAT'S IN THIS WORKBOOK
A6: Hospital Systems | B6: Roll-up of every parent health system, ranked by total licensed beds. Live formulas pull from the Hospitals tab.
A7: Hospitals | B7: Every acute-care, children's, and specialty hospital, grouped by corporate parent, largest to smallest.
A8: LTC Operators | B8: Roll-up of every long-term care corporate operator, ranked by total licensed beds across their Colorado portfolio.
A9: LTC Facilities | B9: ~250 skilled nursing, assisted living, memory care, and CCRC facilities grouped by the company that runs them.
A10: Other Facilities | B10: Rehab hospitals, LTACHs, psychiatric hospitals, surgery centers, dialysis, freestanding ERs, urgent care, clinic networks, cancer centers, imaging, hospice, occupational health.
A12: THREE OWNERSHIP FACTS THAT INVALIDATE MOST DENVER HOSPITAL LISTS
A13: 1. Centura is gone. | B13: Centura Health dissolved in 2023-24. AdventHealth took exactly 5 hospitals (Porter, Littleton, Parker, Avista, Castle Rock); CommonSpirit took the rest. Any list still saying 'Centura' is stale — and using that name in a meeting will cost you credibility.
A14: 2. HCA renamed 9 hospitals Oct 2024. | B14: 'The Medical Center of Aurora' is now HCA HealthONE Aurora. 'North Suburban Medical Center' is now HCA HealthONE Mountain Ridge. Both old names still circulate widely.
A15: 3. A major JV is pending. | B15: AdventHealth and Intermountain signed a definitive agreement on Aug 5, 2026 to combine AdventHealth's 5 Denver hospitals with 3 of Intermountain's (Good Samaritan, Lutheran, Platte Valley). AdventHealth gets majority interest and runs daily ops. Saint Joseph is EXCLUDED and stays with Intermountain. Expected close early 2027, pending CO Attorney General review. If it closes, that's a ~1,940-bed system and the #3 player in the metro — and it means purchasing authority for 8 hospitals is about to move.
A17: HOW TO READ THE COLUMNS
A18: Region | B18: Metro = 7-county Denver metro. Extended = Front Range within roughly a 50-90 minute drive (Fort Collins, Loveland, Greeley, Colorado Springs). Outside metro = the rest of Colorado, included only where an operator's portfolio spans the state.
A19: Licensed Beds | B19: State-authorized maximum, not staffed beds. Staffed counts typically run 25-50% lower. Use licensed beds for sizing the building; ask about census when sizing the order.
A20: Parent / Operator | B20: The corporate entity that controls purchasing. This is the organizing principle of the whole workbook — one contract at this level can cover dozens of buildings.
A21: Notes (add your own) | B21: Blank column for your working notes. Example: "Incumbent = Bunzl, GPO through Premier, contract renews Jun-2027, met w/ EVS Dir 9/12".
A23: WHERE THE LEVERAGE IS
A24: Hospitals | B24: Six systems control roughly 90% of metro beds. HCA HealthONE and UCHealth are effectively tied for #1 and are within ~50 beds of each other. HCA is for-profit and buys through national GPO contracts out of Nashville; UCHealth, Denver Health, and Children's are more locally decided. Know which door you're knocking on.
A25: Long-term care | B25: Five phone calls cover roughly a third of Colorado's licensed LTC beds: Ensign/Endura, Life Care Centers, PACS Group, Vivage-Beecan, and Stellar. All five have centralized purchasing.
A26: A trap worth knowing | B26: Vivage-Beecan is the management company, but many of its buildings are LICENSED under 'Long Peak Operating Company' in state and CMS records. If you research by licensee you will call the wrong office. Purchasing sits with Vivage in Glendale.
A27: Management companies | B27: Cappella Living Solutions and WellAge manage buildings they do not own — so they control purchasing for facilities that will never show up under their name in a property search. Higher-leverage calls than the individual buildings.
A28: Nonprofit CCRC cluster | B28: South metro (Christian Living Communities, Wind Crest, Vi at Highlands Ranch, Covenant Living, Holly Creek, Someren Glen) — multi-building campuses where one contract covers independent living, assisted living, memory care, skilled nursing, plus commercial kitchens and large common areas.
A29: DaVita | B29: Headquartered in Denver at 2000 16th St, with ~2,600 US clinics and ~30 in the metro. A national account whose decision-makers are in your new backyard.
A31: CAVEATS
B32: 1. Licensed vs staffed beds conflict across sources. Where a hospital publishes its own current figure, that was used over the 2018 Medicare cost report.
B33: 2. Post-acute and behavioral health ownership churns through private-equity transactions faster than public sources update. Treat the Other Facilities tab's parent column as a starting point, not gospel.
B34: 3. Ambulatory surgery centers are almost universally physician-JV LLCs. USPI, SCA Health, AmSurg, and Surgery Partners all hold Colorado stakes that are not publicly attributable by site.
B35: 4. Urgent care is not a state license class, so those counts come from company websites and are the softest numbers here.
B36: 5. Independent living units at CCRCs are generally unlicensed and therefore absent from state bed data — campuses like Wind Crest (~1,300-1,500 IL apartments) are far larger than their licensed bed count suggests.
A38: SOURCES
B39: CMS Care Compare nursing home provider dataset (July 2026); CDPHE Health Facilities licensing registry (~5,014 facilities); Becker's Hospital Review; Healthcare Dive; Colorado Sun; Fierce Healthcare; system and facility websites (HCA HealthONE, UCHealth, CommonSpirit Mountain Region, AdventHealth, Intermountain, Denver Health, Children's Colorado); Colorado Health Care Association; Colorado Community Health Network.

Sheet Hospital Systems
A1: Hospital Systems — Ranked by Total Licensed Beds
A2: Live roll-up from the Hospitals tab. This is your call list: six systems control roughly 90% of metro beds.
A4: # | B4: Parent System | C4: Ownership Type | D4: Hospitals | E4: Total Licensed Beds | F4: Notes (add your own)
A5: 1 | B5: HCA HealthONE (HCA Healthcare) | C5: For-profit, publicly traded (NYSE: HCA) | D5: =COUNTIF(Hospitals!$D$5:$D$58,$B5) -> 8 | E5: =SUMIF(Hospitals!$D$5:$D$58,$B5,Hospitals!$E$5:$E$58) -> 2471 | F5: Largest metro system. Buys through national GPO contracts out of Nashville — local EVS directors influence, corporate decides. Renamed 9 CO hospitals Oct 2024.
A6: 2 | B6: UCHealth | C6: Nonprofit / state-affiliated | D6: =COUNTIF(Hospitals!$D$5:$D$58,$B6) -> 10 | E6: =SUMIF(Hospitals!$D$5:$D$58,$B6,Hospitals!$E$5:$E$58) -> 2318 | F6: Effectively tied with HCA for #1. Academic flagship at Anschutz. More locally decided than HCA.
A7: 3 | B7: CommonSpirit Health (Mountain Region) | C7: Nonprofit Catholic | D7: =COUNTIF(Hospitals!$D$5:$D$58,$B7) -> 7 | E7: =SUMIF(Hospitals!$D$5:$D$58,$B7,Hospitals!$E$5:$E$58) -> 1324 | F7: Took 12 of the former Centura Colorado hospitals in the 2023-24 split. National Catholic system, Chicago HQ.
A8: 4 | B8: AdventHealth Rocky Mountain Region | C8: Nonprofit, Seventh-day Adventist | D8: =COUNTIF(Hospitals!$D$5:$D$58,$B8) -> 5 | E8: =SUMIF(Hospitals!$D$5:$D$58,$B8,Hospitals!$E$5:$E$58) -> 978 | F8: Took exactly 5 Centura hospitals. PENDING JV with Intermountain — will run 8 Denver hospitals if it closes early 2027.
A9: 5 | B9: Intermountain Health | C9: Nonprofit (formerly SCL Health) | D9: =COUNTIF(Hospitals!$D$5:$D$58,$B9) -> 4 | E9: =SUMIF(Hospitals!$D$5:$D$58,$B9,Hospitals!$E$5:$E$58) -> 958 | F9: 3 of its 4 CO hospitals are in the pending AdventHealth JV. Saint Joseph stays with Intermountain.
A10: 6 | B10: Children's Hospital Colorado | C10: Independent nonprofit | D10: =COUNTIF(Hospitals!$D$5:$D$58,$B10) -> 4 | E10: =SUMIF(Hospitals!$D$5:$D$58,$B10,Hospitals!$E$5:$E$58) -> 543 | F10: Only ACS-verified Level I Pediatric Trauma Center in Colorado. Top-10 nationally.
A11: 7 | B11: Denver Health (public authority) | C11: Public safety-net authority | D11: =COUNTIF(Hospitals!$D$5:$D$58,$B11) -> 1 | E11: =SUMIF(Hospitals!$D$5:$D$58,$B11,Hospitals!$E$5:$E$58) -> 525 | F11: Public safety-net. Political subdivision of the State of Colorado — expect public procurement rules and formal bidding.
A12: 8 | B12: US Dept. of Veterans Affairs | C12: Federal | D12: =COUNTIF(Hospitals!$D$5:$D$58,$B12) -> 1 | E12: =SUMIF(Hospitals!$D$5:$D$58,$B12,Hospitals!$E$5:$E$58) -> 187 | F12: Federal procurement. Requires SAM registration and likely a GSA/FSS schedule or VA contract vehicle.
A13: 9 | B13: Boulder Community Health (independent) | C13: Independent nonprofit | D13: =COUNTIF(Hospitals!$D$5:$D$58,$B13) -> 1 | E13: =SUMIF(Hospitals!$D$5:$D$58,$B13,Hospitals!$E$5:$E$58) -> 167 | F13: One of Colorado's last independent community hospitals. Local decision-making.
A14: 10 | B14: Craig Hospital (independent nonprofit) | C14: Independent nonprofit | D14: =COUNTIF(Hospitals!$D$5:$D$58,$B14) -> 1 | E14: =SUMIF(Hospitals!$D$5:$D$58,$B14,Hospitals!$E$5:$E$58) -> 93 | F14: Independent nonprofit, nationally ranked neurorehab. Single-site decision.
A15: 11 | B15: National Jewish Health (independent) | C15: Independent nonprofit | D15: =COUNTIF(Hospitals!$D$5:$D$58,$B15) -> 1 | E15: =SUMIF(Hospitals!$D$5:$D$58,$B15,Hospitals!$E$5:$E$58) -> 46 | F15: #1 respiratory hospital in the US. Single site; partners with Saint Joseph.
B16: TOTAL | D16: =SUM(D5:D15) -> 43 | E16: =SUM(E5:E15) -> 9610
B18: Top 6 systems as % of all listed beds: | E18: =SUM(E5:E10)/E16 -> 0.89406868
B20: If the AdventHealth-Intermountain JV closes (expected early 2027), AdventHealth + Good Samaritan + Lutheran + Platte Valley combine into a ~1,940-bed system, and Intermountain drops to one Colorado hospital.

Sheet Hospitals
A1: Hospitals — Denver Metro and Front Range, by Corporate Parent
A2: Grouped by parent health system (systems ordered by total beds), hospitals within each system ordered largest to smallest.
A4: # | B4: Hospital | C4: City | D4: Parent System | E4: Licensed Beds | F4: Type | G4: Region | H4: Notes (add your own)
A5: HCA HealthONE (HCA Healthcare) — 8 hospital(s), 2,471 licensed beds
A6: 1 | B6: HCA HealthONE Presbyterian St. Luke's | C6: Denver | D6: HCA HealthONE (HCA Healthcare) | E6: 680 | F6: General acute / tertiary | G6: Metro | H6: Solid organ + bone marrow transplant; Colorado Blood Cancer Institute
A7: 2 | B7: HCA HealthONE Swedish | C7: Englewood | D7: HCA HealthONE (HCA Healthcare) | E7: 504 | F7: General acute | G7: Metro | H7: LEVEL I TRAUMA; burn center; state's first Comprehensive Stroke Center; 21 ORs
A8: 3 | B8: HCA HealthONE Rose | C8: Denver | D8: HCA HealthONE (HCA Healthcare) | E8: 422 | F8: General acute | G8: Metro | H8: Magnet since 2017; women's services / NICU
A9: 4 | B9: HCA HealthONE Aurora | C9: Aurora | D9: HCA HealthONE (HCA Healthcare) | E9: 346 | F9: General acute | G9: Metro | H9: RENAMED Oct 2024 (was The Medical Center of Aurora). Level II Trauma; 84-bed cardiac tower
A10: 5 | B10: HCA HealthONE Sky Ridge | C10: Lone Tree | D10: HCA HealthONE (HCA Healthcare) | E10: 284 | F10: General acute | G10: Metro | H10: Level II Trauma; Douglas County's first hospital
A11: 6 | B11: HCA HealthONE Mountain Ridge | C11: Thornton | D11: HCA HealthONE (HCA Healthcare) | E11: 157 | F11: General acute | G11: Metro | H11: RENAMED Oct 2024 (was North Suburban Medical Center). Level II Trauma
A12: 7 | B12: HCA HealthONE Spalding Rehabilitation | C12: Aurora | D12: HCA HealthONE (HCA Healthcare) | E12: 78 | F12: Inpatient rehab | G12: Metro | H12: Colorado's first licensed rehab hospital (1965)
A13: 8 | B13: HCA HealthONE Rocky Mountain Children's | C13: Denver | D13: HCA HealthONE (HCA Healthcare) | F13: Children's | G13: Metro | H13: Hospital-within-hospital at Presbyterian St. Luke's (~53 beds) - NOT counted separately
A14: UCHealth — 10 hospital(s), 2,318 licensed beds
A15: 9 | B15: UCHealth University of Colorado Hospital | C15: Aurora | D15: UCHealth | E15: 698 | F15: Academic medical center | G15: Metro | H15: LEVEL I TRAUMA; principal teaching hospital, CU School of Medicine; Anschutz campus
A16: 10 | B16: UCHealth Memorial Hospital Central | C16: Colorado Springs | D16: UCHealth | E16: 413 | F16: General acute | G16: Extended | H16: Level I Trauma; Comprehensive Stroke Center
A17: 11 | B17: UCHealth Memorial Hospital North | C17: Colorado Springs | D17: UCHealth | E17: 300 | F17: General acute | G17: Extended | H17: Approximate - shares a 713-bed combined license with Central
A18: 12 | B18: UCHealth Poudre Valley Hospital | C18: Fort Collins | D18: UCHealth | E18: 270 | F18: General acute | G18: Extended | H18: Sources vary 270-300; NICU; hyperbarics
A19: 13 | B19: UCHealth Medical Center of the Rockies | C19: Loveland | D19: UCHealth | E19: 216 | F19: General acute | G19: Extended | H19: Level I Trauma; cardiac specialty; LifeLine air transport
A20: 14 | B20: UCHealth Highlands Ranch Hospital | C20: Highlands Ranch | D20: UCHealth | E20: 147 | F20: General acute | G20: Metro | H20: Opened 2019; $119M expansion underway
A21: 15 | B21: UCHealth Longs Peak Hospital | C21: Longmont | D21: UCHealth | E21: 89 | F21: General acute | G21: Metro | H21: Primary Stroke Center
A22: 16 | B22: UCHealth Greeley Hospital | C22: Greeley | D22: UCHealth | E22: 88 | F22: General acute | G22: Extended | H22: Opened 2019; expanded 2023
A23: 17 | B23: UCHealth Grandview Hospital | C23: Colorado Springs | D23: UCHealth | E23: 57 | F23: General acute / ortho | G23: Extended | H23: Joint Commission-certified hip & knee replacement
A24: 18 | B24: UCHealth Broomfield Hospital | C24: Broomfield | D24: UCHealth | E24: 40 | F24: Community acute | G24: Metro | H24: Opened 2016
A25: CommonSpirit Health (Mountain Region) — 7 hospital(s), 1,324 licensed beds
A26: 19 | B26: CommonSpirit St. Francis Hospital | C26: Colorado Springs | D26: CommonSpirit Health (Mountain Region) | E26: 317 | F26: General acute | G26: Extended | H26: Level III Trauma; Level III NICU; Flight For Life home base
A27: 20 | B27: CommonSpirit Penrose Hospital | C27: Colorado Springs | D27: CommonSpirit Health (Mountain Region) | E27: 300 | F27: General acute | G27: Extended | H27: Level II state / Level I ACS-verified trauma; cancer & cardiac referral center
A28: 21 | B28: CommonSpirit St. Anthony Hospital | C28: Lakewood | D28: CommonSpirit Health (Mountain Region) | E28: 237 | F28: General acute | G28: Metro | H28: LEVEL I TRAUMA + Comprehensive Stroke; HQ of Flight For Life Colorado
A29: 22 | B29: CommonSpirit St. Anthony North Hospital | C29: Westminster | D29: CommonSpirit Health (Mountain Region) | E29: 206 | F29: General acute | G29: Metro | H29: Level III Trauma; new bed tower 2024 (237 at full build-out)
A30: 23 | B30: Longmont United Hospital | C30: Longmont | D30: CommonSpirit Health (Mountain Region) | E30: 186 | F30: General acute | G30: Metro | H30: Level III Trauma; Level II NICU. Confirmed CommonSpirit, not AdventHealth
A31: 24 | B31: OrthoColorado Hospital | C31: Lakewood | D31: CommonSpirit Health (Mountain Region) | E31: 48 | F31: Specialty - ortho/spine | G31: Metro | H31: JV with local ortho practices; only ortho/spine specialty hospital in the Rockies
A32: 25 | B32: CommonSpirit St. Francis Hospital - Interquest | C32: Colorado Springs | D32: CommonSpirit Health (Mountain Region) | E32: 30 | F32: Neighborhood acute | G32: Extended | H32: Approximate; newer small-format hospital
A33: AdventHealth Rocky Mountain Region — 5 hospital(s), 978 licensed beds
A34: 26 | B34: AdventHealth Porter | C34: Denver | D34: AdventHealth Rocky Mountain Region | E34: 368 | F34: General acute / tertiary | G34: Metro | H34: Level III Trauma; organ transplant (kidney/liver/pancreas); behavioral health; teaching hospital
A35: 27 | B35: AdventHealth Littleton | C35: Littleton | D35: AdventHealth Rocky Mountain Region | E35: 231 | F35: General acute / tertiary | G35: Metro | H35: Level II Trauma; Comprehensive Stroke; heart & vascular tower opened Aug 2025
A36: 28 | B36: AdventHealth Parker | C36: Parker | D36: AdventHealth Rocky Mountain Region | E36: 179 | F36: General acute / tertiary | G36: Metro | H36: Level II Trauma; $300M seven-story tower broke ground Jan 2025
A37: 29 | B37: AdventHealth Avista | C37: Louisville | D37: AdventHealth Rocky Mountain Region | E37: 114 | F37: General acute | G37: Metro | H37: Level III Trauma; replacement hospital planned at 123 beds
A38: 30 | B38: AdventHealth Castle Rock | C38: Castle Rock | D38: AdventHealth Rocky Mountain Region | E38: 86 | F38: General acute | G38: Metro | H38: Level III Trauma; cancer center opened Feb 2026
A39: Intermountain Health — 4 hospital(s), 958 licensed beds
A40: 31 | B40: Intermountain Health Saint Joseph Hospital | C40: Denver | D40: Intermountain Health | E40: 400 | F40: General acute | G40: Metro | H40: EXCLUDED from the pending AdventHealth JV - stays with Intermountain
A41: 32 | B41: Intermountain Health Good Samaritan Hospital | C41: Lafayette | D41: Intermountain Health | E41: 234 | F41: General acute | G41: Metro | H41: Level II Trauma. IN PENDING ADVENTHEALTH JV
...

Sheet LTC Operators
A1: Long-Term Care Operators — Ranked by Total Licensed Beds
A2: Live roll-up from the LTC Facilities tab. One contract at this level can cover dozens of buildings.
A4: # | B4: Corporate Operator | C4: Facilities | D4: Total Licensed Beds | E4: Metro Facilities | F4: Notes (add your own)
A5: 1 | B5: The Ensign Group (Endura Healthcare) | C5: =COUNTIF('LTC Facilities'!$D$5:$D$316,$B5) -> 33 | D5: =SUMIF('LTC Facilities'!$D$5:$D$316,$B5,'LTC Facilities'!$E$5:$E$316) -> 3664 | E5: =COUNTIFS('LTC Facilities'!$D$5:$D$316,$B5,'LTC Facilities'!$G$5:$G$316,"Metro") -> 22 | F5: LARGEST LTC operator in Colorado. Decentralized by design — each building is its own operating subsidiary with local P&L authority — but Endura Healthcare (Dave Jorgensen) is the right entry point for a portfolio deal.
A6: 2 | B6: Life Care Centers of America | C6: =COUNTIF('LTC Facilities'!$D$5:$D$316,$B6) -> 22 | D6: =SUMIF('LTC Facilities'!$D$5:$D$316,$B6,'LTC Facilities'!$E$5:$E$316) -> 2929 | E6: =COUNTIFS('LTC Facilities'!$D$5:$D$316,$B6,'LTC Facilities'!$G$5:$G$316,"Metro") -> 12 | F6: Cleveland TN, privately held (Forrest Preston). Centralized purchasing.
A7: 3 | B7: PACS Group (NYSE: PACS) | C7: =COUNTIF('LTC Facilities'!$D$5:$D$316,$B7) -> 19 | D7: =SUMIF('LTC Facilities'!$D$5:$D$316,$B7,'LTC Facilities'!$E$5:$E$316) -> 2409 | E7: =COUNTIFS('LTC Facilities'!$D$5:$D$316,$B7,'LTC Facilities'!$G$5:$G$316,"Metro") -> 14 | F7: Utah-based public company. Brands everything '...Post Acute'. Has been under Colorado media and regulatory scrutiny.
A8: 4 | B8: Vivage-Beecan Senior Living | C8: =COUNTIF('LTC Facilities'!$D$5:$D$316,$B8) -> 23 | D8: =SUMIF('LTC Facilities'!$D$5:$D$316,$B8,'LTC Facilities'!$E$5:$E$316) -> 1909 | E8: =COUNTIFS('LTC Facilities'!$D$5:$D$316,$B8,'LTC Facilities'!$G$5:$G$316,"Metro") -> 15 | F8: COLORADO-BASED (Glendale). Merged with Beecan Feb 2023. WATCH OUT: many buildings are licensed under 'Long Peak Operating Company' in state/CMS records — purchasing sits with Vivage.
A9: 5 | B9: Stellar Senior Living | C9: =COUNTIF('LTC Facilities'!$D$5:$D$316,$B9) -> 12 | D9: =SUMIF('LTC Facilities'!$D$5:$D$316,$B9,'LTC Facilities'!$E$5:$E$316) -> 1646 | E9: =COUNTIFS('LTC Facilities'!$D$5:$D$316,$B9,'LTC Facilities'!$G$5:$G$316,"Metro") -> 5 | F9: Utah-based but Colorado is its largest state. Mixed SNF + AL/MC portfolio — good single-contract target.
A10: 6 | B10: MorningStar Senior Living (Denver HQ) | C10: =COUNTIF('LTC Facilities'!$D$5:$D$316,$B10) -> 15 | D10: =SUMIF('LTC Facilities'!$D$5:$D$316,$B10,'LTC Facilities'!$E$5:$E$316) -> 1476 | E10: =COUNTIFS('LTC Facilities'!$D$5:$D$316,$B10,'LTC Facilities'!$G$5:$G$316,"Metro") -> 11 | F10: HEADQUARTERED IN DENVER. AL/IL/MC only, no skilled nursing. 40+ communities across the West.
A11: 7 | B11: Brookdale Senior Living | C11: =COUNTIF('LTC Facilities'!$D$5:$D$316,$B11) -> 12 | D11: =SUMIF('LTC Facilities'!$D$5:$D$316,$B11,'LTC Facilities'!$E$5:$E$316) -> 1225 | E11: =COUNTIFS('LTC Facilities'!$D$5:$D$316,$B11,'LTC Facilities'!$G$5:$G$316,"Metro") -> 9 | F11: Largest US senior living operator. Mostly AL/IL/MC in Colorado plus two SNF units. 11 additional IL-only communities carry no licensed beds.
A12: 8 | B12: Independent | C12: =COUNTIF('LTC Facilities'!$D$5:$D$316,$B12) -> 6 | D12: =SUMIF('LTC Facilities'!$D$5:$D$316,$B12,'LTC Facilities'!$E$5:$E$316) -> 1113 | E12: =COUNTIFS('LTC Facilities'!$D$5:$D$316,$B12,'LTC Facilities'!$G$5:$G$316,"Metro") -> 6 | F12: Large single-site buildings with no corporate parent — local decision-makers, faster sales cycles, but one building per contract.
A13: 9 | B13: Bello / Maze / Swain / Myers family group (Accel) | C13: =COUNTIF('LTC Facilities'!$D$5:$D$316,$B13) -> 9 | D13: =SUMIF('LTC Facilities'!$D$5:$D$316,$B13,'LTC Facilities'!$E$5:$E$316) -> 709 | E13: =COUNTIFS('LTC Facilities'!$D$5:$D$316,$B13,'LTC Facilities'!$G$5:$G$316,"Metro") -> 1
A14: 10 | B14: Sunrise Senior Living | C14: =COUNTIF('LTC Facilities'!$D$5:$D$316,$B14) -> 6 | D14: =SUMIF('LTC Facilities'!$D$5:$D$316,$B14,'LTC Facilities'!$E$5:$E$316) -> 675 | E14: =COUNTIFS('LTC Facilities'!$D$5:$D$316,$B14,'LTC Facilities'!$G$5:$G$316,"Metro") -> 6 | F14: 6 communities, ALL in the Denver metro. Tight geographic cluster.
A15: 11 | B15: Bethesda Senior Living Communities | C15: =COUNTIF('LTC Facilities'!$D$5:$D$316,$B15) -> 6 | D15: =SUMIF('LTC Facilities'!$D$5:$D$316,$B15,'LTC Facilities'!$E$5:$E$316) -> 646 | E15: =COUNTIFS('LTC Facilities'!$D$5:$D$316,$B15,'LTC Facilities'!$G$5:$G$316,"Metro") -> 1 | F15: Colorado Springs nonprofit. Only one metro building (Thornton).
A16: 12 | B16: Veritas Management Group | C16: =COUNTIF('LTC Facilities'!$D$5:$D$316,$B16) -> 8 | D16: =SUMIF('LTC Facilities'!$D$5:$D$316,$B16,'LTC Facilities'!$E$5:$E$316) -> 636 | E16: =COUNTIFS('LTC Facilities'!$D$5:$D$316,$B16,'LTC Facilities'!$G$5:$G$316,"Metro") -> 3
A17: 13 | B17: Centennial Healthcare | C17: =COUNTIF('LTC Facilities'!$D$5:$D$316,$B17) -> 8 | D17: =SUMIF('LTC Facilities'!$D$5:$D$316,$B17,'LTC Facilities'!$E$5:$E$316) -> 610 | E17: =COUNTIFS('LTC Facilities'!$D$5:$D$316,$B17,'LTC Facilities'!$G$5:$G$316,"Metro") -> 0
A18: 14 | B18: Madison Creek Partners | C18: =COUNTIF('LTC Facilities'!$D$5:$D$316,$B18) -> 8 | D18: =SUMIF('LTC Facilities'!$D$5:$D$316,$B18,'LTC Facilities'!$E$5:$E$316) -> 596 | E18: =COUNTIFS('LTC Facilities'!$D$5:$D$316,$B18,'LTC Facilities'!$G$5:$G$316,"Metro") -> 2
A19: 15 | B19: State of Colorado (Veterans Community Living Centers) | C19: =COUNTIF('LTC Facilities'!$D$5:$D$316,$B19) -> 5 | D19: =SUMIF('LTC Facilities'!$D$5:$D$316,$B19,'LTC Facilities'!$E$5:$E$316) -> 554 | E19: =COUNTIFS('LTC Facilities'!$D$5:$D$316,$B19,'LTC Facilities'!$G$5:$G$316,"Metro") -> 1 | F19: Operated by Colorado Dept. of Human Services. State procurement rules apply.
A20: 16 | B20: Columbine Health Systems | C20: =COUNTIF('LTC Facilities'!$D$5:$D$316,$B20) -> 5 | D20: =SUMIF('LTC Facilities'!$D$5:$D$316,$B20,'LTC Facilities'!$E$5:$E$316) -> 500 | E20: =COUNTIFS('LTC Facilities'!$D$5:$D$316,$B20,'LTC Facilities'!$G$5:$G$316,"Metro") -> 0 | F20: Family-owned, Fort Collins/Larimer County only. Not metro.
A21: 17 | B21: Ciel Senior Living | C21: =COUNTIF('LTC Facilities'!$D$5:$D$316,$B21) -> 5 | D21: =SUMIF('LTC Facilities'!$D$5:$D$316,$B21,'LTC Facilities'!$E$5:$E$316) -> 482 | E21: =COUNTIFS('LTC Facilities'!$D$5:$D$316,$B21,'LTC Facilities'!$G$5:$G$316,"Metro") -> 5 | F21: 5 communities, all Denver metro. Several licensed under legal entity names (Ridge Pinehurst LLC, Stonebridge Senior LLC) — hard to find by brand.
A22: 18 | B22: Christian Living Communities / Cappella | C22: =COUNTIF('LTC Facilities'!$D$5:$D$316,$B22) -> 7 | D22: =SUMIF('LTC Facilities'!$D$5:$D$316,$B22,'LTC Facilities'!$E$5:$E$316) -> 439 | E22: =COUNTIFS('LTC Facilities'!$D$5:$D$316,$B22,'LTC Facilities'!$G$5:$G$316,"Metro") -> 4 | F22: Greenwood Village nonprofit. Cappella Living Solutions is its third-party MANAGEMENT arm — it controls purchasing for buildings it doesn't own.
A23: 19 | B23: Balfour Senior Living (Kisco Senior Living) | C23: =COUNTIF('LTC Facilities'!$D$5:$D$316,$B23) -> 6 | D23: =SUMIF('LTC Facilities'!$D$5:$D$316,$B23,'LTC Facilities'!$E$5:$E$316) -> 433 | E23: =COUNTIFS('LTC Facilities'!$D$5:$D$316,$B23,'LTC Facilities'!$G$5:$G$316,"Metro") -> 6 | F23: Colorado-founded (Louisville CO), now owned by Kisco. All 6 communities in metro/Boulder County.
A24: 20 | B24: Ivy Living | C24: =COUNTIF('LTC Facilities'!$D$5:$D$316,$B24) -> 4 | D24: =SUMIF('LTC Facilities'!$D$5:$D$316,$B24,'LTC Facilities'!$E$5:$E$316) -> 404 | E24: =COUNTIFS('LTC Facilities'!$D$5:$D$316,$B24,'LTC Facilities'!$G$5:$G$316,"Metro") -> 2
A25: 21 | B25: Frontline Management | C25: =COUNTIF('LTC Facilities'!$D$5:$D$316,$B25) -> 5 | D25: =SUMIF('LTC Facilities'!$D$5:$D$316,$B25,'LTC Facilities'!$E$5:$E$316) -> 389 | E25: =COUNTIFS('LTC Facilities'!$D$5:$D$316,$B25,'LTC Facilities'!$G$5:$G$316,"Metro") -> 1
A26: 22 | B26: Sweetwater Care | C26: =COUNTIF('LTC Facilities'!$D$5:$D$316,$B26) -> 4 | D26: =SUMIF('LTC Facilities'!$D$5:$D$316,$B26,'LTC Facilities'!$E$5:$E$316) -> 338 | E26: =COUNTIFS('LTC Facilities'!$D$5:$D$316,$B26,'LTC Facilities'!$G$5:$G$316,"Metro") -> 3
A27: 23 | B27: American Baptist Homes of the Midwest | C27: =COUNTIF('LTC Facilities'!$D$5:$D$316,$B27) -> 2 | D27: =SUMIF('LTC Facilities'!$D$5:$D$316,$B27,'LTC Facilities'!$E$5:$E$316) -> 323 | E27: =COUNTIFS('LTC Facilities'!$D$5:$D$316,$B27,'LTC Facilities'!$G$5:$G$316,"Metro") -> 2
A28: 24 | B28: Erickson Senior Living | C28: =COUNTIF('LTC Facilities'!$D$5:$D$316,$B28) -> 1 | D28: =SUMIF('LTC Facilities'!$D$5:$D$316,$B28,'LTC Facilities'!$E$5:$E$316) -> 316 | E28: =COUNTIFS('LTC Facilities'!$D$5:$D$316,$B28,'LTC Facilities'!$G$5:$G$316,"Metro") -> 1 | F28: Wind Crest in Highlands Ranch — one of the largest single senior campuses in Colorado. Licensed beds understate it badly: ~1,300-1,500 unlicensed independent living apartments on top.
A29: 25 | B29: Eaton Senior Communities | C29: =COUNTIF('LTC Facilities'!$D$5:$D$316,$B29) -> 1 | D29: =SUMIF('LTC Facilities'!$D$5:$D$316,$B29,'LTC Facilities'!$E$5:$E$316) -> 300 | E29: =COUNTIFS('LTC Facilities'!$D$5:$D$316,$B29,'LTC Facilities'!$G$5:$G$316,"Metro") -> 1
A30: 26 | B30: Good Samaritan Society (Sanford Health) | C30: =COUNTIF('LTC Facilities'!$D$5:$D$316,$B30) -> 5 | D30: =SUMIF('LTC Facilities'!$D$5:$D$316,$B30,'LTC Facilities'!$E$5:$E$316) -> 228 | E30: =COUNTIFS('LTC Facilities'!$D$5:$D$316,$B30,'LTC Facilities'!$G$5:$G$316,"Metro") -> 0 | F30: Northern Colorado only — NO Denver metro presence.
A31: 27 | B31: CommonSpirit Health | C31: =COUNTIF('LTC Facilities'!$D$5:$D$316,$B31) -> 2 | D31: =SUMIF('LTC Facilities'!$D$5:$D$316,$B31,'LTC Facilities'!$E$5:$E$316) -> 215 | E31: =COUNTIFS('LTC Facilities'!$D$5:$D$316,$B31,'LTC Facilities'!$G$5:$G$316,"Metro") -> 1
A32: 28 | B32: Independent (MGL Partners dev.) | C32: =COUNTIF('LTC Facilities'!$D$5:$D$316,$B32) -> 1 | D32: =SUMIF('LTC Facilities'!$D$5:$D$316,$B32,'LTC Facilities'!$E$5:$E$316) -> 207 | E32: =COUNTIFS('LTC Facilities'!$D$5:$D$316,$B32,'LTC Facilities'!$G$5:$G$316,"Metro") -> 1
A33: 29 | B33: Legend Senior Living | C33: =COUNTIF('LTC Facilities'!$D$5:$D$316,$B33) -> 2 | D33: =SUMIF('LTC Facilities'!$D$5:$D$316,$B33,'LTC Facilities'!$E$5:$E$316) -> 206 | E33: =COUNTIFS('LTC Facilities'!$D$5:$D$316,$B33,'LTC Facilities'!$G$5:$G$316,"Metro") -> 1
A34: 30 | B34: Cogir Senior Living | C34: =COUNTIF('LTC Facilities'!$D$5:$D$316,$B34) -> 1 | D34: =SUMIF('LTC Facilities'!$D$5:$D$316,$B34,'LTC Facilities'!$E$5:$E$316) -> 165 | E34: =COUNTIFS('LTC Facilities'!$D$5:$D$316,$B34,'LTC Facilities'!$G$5:$G$316,"Metro") -> 1
A35: 31 | B35: Amira Senior Living | C35: =COUNTIF('LTC Facilities'!$D$5:$D$316,$B35) -> 1 | D35: =SUMIF('LTC Facilities'!$D$5:$D$316,$B35,'LTC Facilities'!$E$5:$E$316) -> 160 | E35: =COUNTIFS('LTC Facilities'!$D$5:$D$316,$B35,'LTC Facilities'!$G$5:$G$316,"Metro") -> 1
A36: 32 | B36: Gardens Care Senior Living | C36: =COUNTIF('LTC Facilities'!$D$5:$D$316,$B36) -> 3 | D36: =SUMIF('LTC Facilities'!$D$5:$D$316,$B36,'LTC Facilities'!$E$5:$E$316) -> 160 | E36: =COUNTIFS('LTC Facilities'!$D$5:$D$316,$B36,'LTC Facilities'!$G$5:$G$316,"Metro") -> 3
A37: 33 | B37: Volunteers of America National Services | C37: =COUNTIF('LTC Facilities'!$D$5:$D$316,$B37) -> 3 | D37: =SUMIF('LTC Facilities'!$D$5:$D$316,$B37,'LTC Facilities'!$E$5:$E$316) -> 146 | E37: =COUNTIFS('LTC Facilities'!$D$5:$D$316,$B37,'LTC Facilities'!$G$5:$G$316,"Metro") -> 0 | F37: VOA Colorado's metro footprint is unlicensed affordable senior housing, not licensed LTC.
A38: 34 | B38: Juniper Communities | C38: =COUNTIF('LTC Facilities'!$D$5:$D$316,$B38) -> 3 | D38: =SUMIF('LTC Facilities'!$D$5:$D$316,$B38,'LTC Facilities'!$E$5:$E$316) -> 135 | E38: =COUNTIFS('LTC Facilities'!$D$5:$D$316,$B38,'LTC Facilities'!$G$5:$G$316,"Metro") -> 3
A39: 35 | B39: Clear Choice Healthcare | C39: =COUNTIF('LTC Facilities'!$D$5:$D$316,$B39) -> 1 | D39: =SUMIF('LTC Facilities'!$D$5:$D$316,$B39,'LTC Facilities'!$E$5:$E$316) -> 133 | E39: =COUNTIFS('LTC Facilities'!$D$5:$D$316,$B39,'LTC Facilities'!$G$5:$G$316,"Metro") -> 1
A40: 36 | B40: Advanced Health Care | C40: =COUNTIF('LTC Facilities'!$D$5:$D$316,$B40) -> 3 | D40: =SUMIF('LTC Facilities'!$D$5:$D$316,$B40,'LTC Facilities'!$E$5:$E$316) -> 124 | E40: =COUNTIFS('LTC Facilities'!$D$5:$D$316,$B40,'LTC Facilities'!$G$5:$G$316,"Metro") -> 2
A41: 37 | B41: Covenant Living Communities | C41: =COUNTIF('LTC Facilities'!$D$5:$D$316,$B41) -> 1 | D41: =SUMIF('LTC Facilities'!$D$5:$D$316,$B41,'LTC Facilities'!$E$5:$E$316) -> 120 | E41: =COUNTIFS('LTC Facilities'!$D$5:$D$316,$B41,'LTC Facilities'!$G$5:$G$316,"Metro") -> 1
...

Sheet LTC Facilities
A1: Long-Term Care Facilities — Grouped by Corporate Operator
A2: Skilled nursing, assisted living, memory care and CCRCs. Operators ordered by total beds; facilities within each ordered largest to smallest.
A4: # | B4: Facility | C4: City | D4: Corporate Operator | E4: Licensed Beds | F4: Care Type | G4: Region | H4: Notes (add your own)
A5: The Ensign Group (Endura Healthcare) — 33 facilities (22 in metro), 3,664 licensed beds
A6: 1 | B6: Hampden Hills Post Acute | C6: Aurora | D6: The Ensign Group (Endura Healthcare) | E6: 218 | F6: Skilled nursing | G6: Metro
A7: 2 | B7: Oakwood Care and Rehabilitation | C7: Lakewood | D7: The Ensign Group (Endura Healthcare) | E7: 170 | F7: Skilled nursing | G7: Metro
A8: 3 | B8: Malley Transitional Care Center | C8: Northglenn | D8: The Ensign Group (Endura Healthcare) | E8: 162 | F8: Skilled nursing | G8: Metro
A9: 4 | B9: The Villas at Sunny Acres | C9: Thornton | D9: The Ensign Group (Endura Healthcare) | E9: 160 | F9: Skilled nursing | G9: Metro | H9: On CCRC campus
A10: 5 | B10: Parker Post Acute | C10: Parker | D10: The Ensign Group (Endura Healthcare) | E10: 154 | F10: Skilled nursing | G10: Metro
A11: 6 | B11: Rock Canyon Respiratory & Rehabilitation | C11: Pueblo | D11: The Ensign Group (Endura Healthcare) | E11: 151 | F11: Skilled nursing | G11: Outside metro
A12: 7 | B12: Boulder Canyon Health & Rehabilitation | C12: Boulder | D12: The Ensign Group (Endura Healthcare) | E12: 140 | F12: Skilled nursing | G12: Metro
A13: 8 | B13: Holly Heights Care & Rehabilitation | C13: Denver | D13: The Ensign Group (Endura Healthcare) | E13: 133 | F13: Skilled nursing | G13: Metro
A14: 9 | B14: Durango Health & Rehabilitation | C14: Durango | D14: The Ensign Group (Endura Healthcare) | E14: 133 | F14: Skilled nursing | G14: Outside metro
A15: 10 | B15: The Springs at St. Andrews Village | C15: Aurora | D15: The Ensign Group (Endura Healthcare) | E15: 130 | F15: SNF + assisted living | G15: Metro | H15: 58 SNF + 72 AL
A16: 11 | B16: Julia Temple Healthcare Center | C16: Englewood | D16: The Ensign Group (Endura Healthcare) | E16: 128 | F16: Skilled nursing | G16: Metro
A17: 12 | B17: City Park Healthcare & Rehabilitation | C17: Denver | D17: The Ensign Group (Endura Healthcare) | E17: 125 | F17: Skilled nursing | G17: Metro
A18: 13 | B18: Ridgeview Post Acute | C18: Commerce City | D18: The Ensign Group (Endura Healthcare) | E18: 112 | F18: Skilled nursing | G18: Metro
A19: 14 | B19: McIntosh Care & Rehabilitation | C19: Longmont | D19: The Ensign Group (Endura Healthcare) | E19: 110 | F19: Skilled nursing | G19: Metro
A20: 15 | B20: Brighton Care Center | C20: Brighton | D20: The Ensign Group (Endura Healthcare) | E20: 108 | F20: Skilled nursing | G20: Metro
A21: 16 | B21: Westlake Health & Rehabilitation | C21: Greeley | D21: The Ensign Group (Endura Healthcare) | E21: 107 | F21: Skilled nursing | G21: Extended
A22: 17 | B22: Lakeshore Post Acute | C22: Pueblo | D22: The Ensign Group (Endura Healthcare) | E22: 106 | F22: Skilled nursing | G22: Outside metro
A23: 18 | B23: Rehabilitation & Nursing Center of the Rockies | C23: Fort Collins | D23: The Ensign Group (Endura Healthcare) | E23: 106 | F23: Skilled nursing | G23: Extended
A24: 19 | B24: South Valley Post Acute | C24: Denver | D24: The Ensign Group (Endura Healthcare) | E24: 106 | F24: Skilled nursing | G24: Metro
A25: 20 | B25: Pelican Pointe Health & Rehabilitation | C25: Windsor | D25: The Ensign Group (Endura Healthcare) | E25: 104 | F25: Skilled nursing | G25: Extended
A26: 21 | B26: The Rehabilitation Center at Sandalwood | C26: Wheat Ridge | D26: The Ensign Group (Endura Healthcare) | E26: 103 | F26: Skilled nursing | G26: Metro
A27: 22 | B27: Broadview Health & Rehabilitation | C27: Greeley | D27: The Ensign Group (Endura Healthcare) | E27: 100 | F27: Skilled nursing | G27: Extended
... A38: 33 | B38: Littleton Care & Rehabilitation | C38: Littleton | D38: The Ensign Group (Endura Healthcare) | E38: 35 | F38: Skilled nursing | G38: Metro
A39: Life Care Centers of America — 22 facilities (12 in metro), 2,929 licensed beds
A40: 34 | B40: Life Care Center of Longmont | C40: Longmont | D40: Life Care Centers of America | E40: 257 | F40: SNF + assisted living | G40: Metro | H40: 187 SNF + 70 AL (The Bridge)
A41: 35 | B41: Briarwood Health Care Center | C41: Denver | D41: Life Care Centers of America | E41: 201 | F41: Skilled nursing | G41: Metro
A42: 36 | B42: Life Care Center of Greeley | C42: Greeley | D42: Life Care Centers of America | E42: 194 | F42: SNF + assisted living | G42: Extended | H42: 124 SNF + 70 AL (The Bridge)
A43: 37 | B43: Life Care Center of Pueblo | C43: Pueblo | D43: Life Care Centers of America | E43: 187 | F43: Skilled nursing | G43: Outside metro
A44: 38 | B44: University Park Care Center | C44: Pueblo | D44: Life Care Centers of America | E44: 180 | F44: Skilled nursing | G44: Outside metro
A45: 39 | B45: Life Care Center of Aurora | C45: Aurora | D45: Life Care Centers of America | E45: 166 | F45: Skilled nursing | G45: Metro
A46: 40 | B46: Hallmark Nursing Center | C46: Denver | D46: Life Care Centers of America | E46: 143 | F46: Skilled nursing | G46: Metro
A47: 41 | B47: Western Hills Health Care Center | C47: Lakewood | D47: Life Care Centers of America | E47: 140 | F47: Skilled nursing | G47: Metro
A48: 42 | B48: Life Care Center of Colorado Springs | C48: Colorado Springs | D48: Life Care Centers of America | E48: 121 | F48: Skilled nursing | G48: Extended
A49: 43 | B49: Life Care Center of Evergreen | C49: Evergreen | D49: Life Care Centers of America | E49: 120 | F49: Skilled nursing | G49: Metro
A50: 44 | B50: Life Care Center of Westminster | C50: Westminster | D50: Life Care Centers of America | E50: 120 | F50: Skilled nursing | G50: Metro
A51: 45 | B51: Life Care Center of Littleton | C51: Littleton | D51: Life Care Centers of America | E51: 120 | F51: Skilled nursing | G51: Metro
...

Sheet Other Facilities
A1: Other Healthcare Facilities — Denver Metro
A2: Everything that is not a general acute-care hospital or a nursing home. Categories ordered by likely cleaning-supply value; entries within each ordered largest to smallest.
A4: # | B4: Facility / Organization | C4: City | D4: Parent / Operator | E4: Size | F4: Unit | G4: Category | H4: Notes (add your own)
A5: BEHAVIORAL HEALTH / PSYCHIATRIC HOSPITALS — 8 entries
A6: 1 | B6: Colorado Mental Health Hospital in Fort Logan | C6: Denver | D6: State of Colorado (CDHS) | E6: 154 | F6: licensed beds | G6: Behavioral health / psychiatric hospitals | H6: Sources vary 94-154; 154 is the CDPHE licensed figure
A7: 2 | B7: West Pines Behavioral Hospital | C7: Westminster | D7: Intermountain Health + Acadia Healthcare JV | E7: 144 | F7: licensed beds | G7: Behavioral health / psychiatric hospitals | H7: Opened 2024 - new build
A8: 3 | B8: HCA HealthONE Mental Health & Wellness Center | C8: Aurora | D8: HCA Healthcare | E8: 120 | F8: licensed beds | G8: Behavioral health / psychiatric hospitals | H8: Part of HCA HealthONE Aurora
A9: 4 | B9: Centennial Peaks Hospital | C9: Louisville | D9: Universal Health Services (UHS) | E9: 104 | F9: licensed beds | G9: Behavioral health / psychiatric hospitals
A10: 5 | B10: Denver Springs | C10: Englewood | D10: Lifepoint Behavioral Health | E10: 96 | F10: licensed beds | G10: Behavioral health / psychiatric hospitals | H10: Formerly Springstone
A11: 6 | B11: Highlands Behavioral Health System | C11: Highlands Ranch | D11: Universal Health Services (UHS) | E11: 86 | F11: licensed beds | G11: Behavioral health / psychiatric hospitals
A12: 7 | B12: Eating Recovery Center - Lowry | C12: Denver | D12: Eating Recovery Center / Pathlight (PE-backed) | E12: 72 | F12: licensed beds | G12: Behavioral health / psychiatric hospitals
A13: 8 | B13: Eating Recovery Center - A Behavioral Hospital | C13: Denver | D13: Eating Recovery Center / Pathlight (PE-backed) | E13: 36 | F13: licensed beds | G13: Behavioral health / psychiatric hospitals
A14: INPATIENT REHABILITATION HOSPITALS — 8 entries
A15: 9 | B15: Craig Hospital | C15: Englewood | D15: Independent nonprofit | E15: 93 | F15: licensed beds | G15: Inpatient rehabilitation hospitals | H15: National-destination spinal cord injury / TBI rehab. Also appears on the Hospitals tab
A16: 10 | B16: HCA HealthONE Spalding Rehabilitation | C16: Aurora | D16: HCA Healthcare | E16: 78 | F16: licensed beds | G16: Inpatient rehabilitation hospitals | H16: Colorado's first licensed acute rehab hospital
A17: 11 | B17: Encompass Health Rehabilitation Hospital of Littleton | C17: Littleton | D17: Encompass Health (NYSE: EHC) | E17: 60 | F17: licensed beds | G17: Inpatient rehabilitation hospitals | H17: Only Encompass IRF in the metro
A18: 12 | B18: PAM Health Rehabilitation Hospital of Golden | C18: Golden | D18: PAM Health | E18: 50 | F18: licensed beds | G18: Inpatient rehabilitation hospitals
A19: 13 | B19: Reunion Rehabilitation Hospital Denver | C19: Denver | D19: Nobis Rehabilitation Partners | E19: 40 | F19: licensed beds | G19: Inpatient rehabilitation hospitals | H19: Central Park
A20: 14 | B20: Reunion Rehabilitation Hospital Inverness | C20: Englewood | D20: Nobis Rehabilitation Partners | E20: 40 | F20: licensed beds | G20: Inpatient rehabilitation hospitals | H20: ~49,000 SF
A21: 15 | B21: PAM Health Rehabilitation Hospital of Westminster | C21: Westminster | D21: PAM Health | E21: 36 | F21: licensed beds | G21: Inpatient rehabilitation hospitals
A22: 16 | B22: Denver Regional Rehabilitation Hospital | C22: Thornton | D22: Vibra Healthcare | E22: 31 | F22: licensed beds | G22: Inpatient rehabilitation hospitals | H22: Co-located on the Vibra Hospital of Denver campus
A23: LONG-TERM ACUTE CARE HOSPITALS (LTACH) — 5 entries
A24: 17 | B24: Kindred Hospital - Denver | C24: Denver | D24: ScionHealth / Kindred LTAC | E24: 81 | F24: licensed beds | G24: Long-term acute care hospitals (LTACH) | H24: Ownership in flux - verify current parent
A25: 18 | B25: PAM Health Specialty Hospital of Denver | C25: Denver | D25: PAM Health | E25: 63 | F25: licensed beds | G25: Long-term acute care hospitals (LTACH)
A26: 19 | B26: Vibra Hospital of Denver | C26: Thornton | D26: Vibra Healthcare | E26: 54 | F26: licensed beds | G26: Long-term acute care hospitals (LTACH)
A27: 20 | B27: Kindred Hospital Aurora | C27: Aurora | D27: ScionHealth / Kindred LTAC | E27: 37 | F27: licensed beds | G27: Long-term acute care hospitals (LTACH)
A28: 21 | B28: Kindred Hospital - Denver South | C28: Denver | D28: ScionHealth / Kindred LTAC | E28: 28 | F28: licensed beds | G28: Long-term acute care hospitals (LTACH)
A29: AMBULATORY SURGERY CENTERS (ASCS) — 6 entries
A30: 22 | B30: Denver metro ASCs - ALL OPERATORS | C30: Metro-wide | D30: Various | E30: 90 | F30: centers (approx.) | G30: Ambulatory surgery centers (ASCs) | H30: 135 Medicare-certified ASCs statewide; ~85-95 in the metro. By county: Arapahoe ~20, Douglas ~17, Denver ~15, Jefferson ~15, Boulder ~14, Adams ~6
A31: 23 | B31: HCA HealthONE Ambulatory Surgical Centers | C31: Denver | D31: HCA Healthcare | E31: 13 | F31: centers (approx.) | G31: Ambulatory surgery centers (ASCs) | H31: Largest single metro ASC network. HQ 4900 S Monaco St. Includes Rose Surgical, Sky Ridge Surgical, North Suburban Surgery
A32: 24 | B32: UCHealth surgery centers | C32: Metro-wide | D32: UCHealth | E32: 3 | F32: centers | G32: Ambulatory surgery centers (ASCs) | H32: Cherry Creek North, Inverness Orthopedics & Spine, Longs Peak
A33: 25 | B33: Endoscopy Center of the Rockies | C33: Boulder County | D33: Independent GI group | E33: 3 | F33: centers | G33: Ambulatory surgery centers (ASCs) | H33: Boulder, Longmont, Lafayette
A34: 26 | B34: Kaiser Permanente ASCs | C34: Denver / Lone Tree | D34: Kaiser Permanente | E34: 2 | F34: centers | G34: Ambulatory surgery centers (ASCs) | H34: Franklin St (Denver) and Lone Tree
A35: 27 | B35: SCA Health / USPI / AmSurg / Surgery Partners holdings | C35: Metro-wide | D35: Optum, Tenet, Envision, Surgery Partners | F35: not disclosed | G35: Ambulatory surgery centers (ASCs) | H35: National chains hold Colorado stakes but operate under local physician-JV LLC names - not brandable from public sources
A36: DIALYSIS CENTERS — 5 entries
A37: 28 | B37: DaVita Inc. | C37: Denver (HQ) | D37: DaVita Inc. (NYSE: DVA) | E37: 30 | F37: clinics (approx.) | G37: Dialysis centers | H37: HEADQUARTERED IN DENVER (2000 16th St). ~2,600+ US clinics. Metro clinics use place-name branding
A38: 29 | B38: Fresenius Kidney Care | C38: Metro-wide | D38: Fresenius Medical Care | E38: 12 | F38: clinics (approx.) | G38: Dialysis centers | H38: Pavilion, Stapleton, Sloans Lake, Lowry, S. Denver, NE Denver, E. Denver, W. Belleview, W. Hampden, Castle Rock
A39: 30 | B39: Independent 'Kidney Center of...' clinics | C39: Metro-wide | D39: Physician-owned / DaVita JV | E39: 5 | F39: clinics (approx.) | G39: Dialysis centers | H39: Northridge, Westminster, Longmont, Lafayette, Parker
A40: 31 | B40: Hospital-based / academic dialysis | C40: Aurora | D40: UCHealth / Children's Colorado | E40: 3 | F40: units | G40: Dialysis centers | H40: UCH Dialysis Services; Children's Colorado Kidney Center
A41: 32 | B41: US Renal Care | C41: Aurora / Lone Tree | D41: US Renal Care | E41: 3 | F41: clinics | G41: Dialysis centers | H41: Altitude Dialysis (Aurora), Lone Tree
...
